from nose.tools import set_trace, eq_
import datetime
import pkgutil
from api.threem import (
    CirculationParser,
    EventParser,
    ErrorParser,
    #EnkiEventMonitor,
)
from core.model import (
    CirculationEvent,
    Contributor,
    DataSource,
    LicensePool,
    Resource,
    Identifier,
    Edition,
    Timestamp
)
from . import DatabaseTest
from api.circulation_exceptions import *
from api.enki import MockEnkiAPI

class TestErrorParser(object):

    # Some sample error documents.

    NOT_LOANABLE = '<Error xmlns:xsd="http://www.w3.org/2001/XMLSchema" xmlns:xsi="http://www.w3.org/2001/XMLSchema-instance"><Code>Gen-001</Code><Message>the patron document status was CAN_HOLD and not one of CAN_LOAN,RESERVATION</Message></Error>'

    ALREADY_ON_LOAN = '<Error xmlns:xsd="http://www.w3.org/2001/XMLSchema" xmlns:xsi="http://www.w3.org/2001/XMLSchema-instance"><Code>Gen-001</Code><Message>the patron document status was LOAN and not one of CAN_LOAN,RESERVATION</Message></Error>'

    TRIED_TO_RETURN_UNLOANED_BOOK = '<Error xmlns:xsd="http://www.w3.org/2001/XMLSchema" xmlns:xsi="http://www.w3.org/2001/XMLSchema-instance"><Code>Gen-001</Code><Message>The patron has no eBooks checked out</Message></Error>'

    TRIED_TO_HOLD_LOANABLE_BOOK = '<Error xmlns:xsd="http://www.w3.org/2001/XMLSchema" xmlns:xsi="http://www.w3.org/2001/XMLSchema-instance"><Code>Gen-001</Code><Message>the patron document status was CAN_LOAN and not one of CAN_HOLD</Message></Error>'

    TRIED_TO_HOLD_BOOK_ON_LOAN = '<Error xmlns:xsd="http://www.w3.org/2001/XMLSchema" xmlns:xsi="http://www.w3.org/2001/XMLSchema-instance"><Code>Gen-001</Code><Message>the patron document status was LOAN and not one of CAN_HOLD</Message></Error>'

    ALREADY_ON_HOLD = '<Error xmlns:xsd="http://www.w3.org/2001/XMLSchema" xmlns:xsi="http://www.w3.org/2001/XMLSchema-instance"><Code>Gen-001</Code><Message>the patron document status was HOLD and not one of CAN_HOLD</Message></Error>'

    TRIED_TO_CANCEL_NONEXISTENT_HOLD = '<Error xmlns:xsd="http://www.w3.org/2001/XMLSchema" xmlns:xsi="http://www.w3.org/2001/XMLSchema-instance"><Code>Gen-001</Code><Message>The patron does not have the book on hold</Message></Error>'

    TOO_MANY_LOANS = '<Error xmlns:xsd="http://www.w3.org/2001/XMLSchema" xmlns:xsi="http://www.w3.org/2001/XMLSchema-instance"><Code>Gen-001</Code><Message>Patron cannot loan more than 12 documents</Message></Error>'

    def test_exception(self):
        parser = ErrorParser()

        error = parser.process_all(self.NOT_LOANABLE)
        assert isinstance(error, NoAvailableCopies)

        error = parser.process_all(self.ALREADY_ON_LOAN)
        assert isinstance(error, AlreadyCheckedOut)

        error = parser.process_all(self.ALREADY_ON_HOLD)
        assert isinstance(error, AlreadyOnHold)

        error = parser.process_all(self.TOO_MANY_LOANS)
        assert isinstance(error, PatronLoanLimitReached)

        error = parser.process_all(self.TRIED_TO_CANCEL_NONEXISTENT_HOLD)
        assert isinstance(error, NotOnHold)

        error = parser.process_all(self.TRIED_TO_RETURN_UNLOANED_BOOK)
        assert isinstance(error, NotCheckedOut)

        error = parser.process_all(self.TRIED_TO_HOLD_LOANABLE_BOOK)
        assert isinstance(error, CurrentlyAvailable)

        # This is such a weird case we don't have a special
        # exception for it.
        error = parser.process_all(self.TRIED_TO_HOLD_BOOK_ON_LOAN)
        assert isinstance(error, CannotHold)
